Workbook

Sheet Lesson Blocks
B2: 30-Lesson DanceSport Plan, Bruce Lee Method
B3: Every block from the handwritten plan, one row each. Use the filter arrows in row 5 to sort or filter. Phase method notes are on the Phase Map sheet.
B5: Lesson | C5: Phase | D5: Block Order | E5: Minutes | F5: Block Type | G5: Dance | H5: Style | I5: Frame | J5: Steps | K5: Activity Detail
B6: 1 | C6: Phase 1: Foundation Steps 1-3 | D6: 1 | E6: 3 | F6: Warm Up | G6: All | H6: General | I6: N/A | J6: N/A | K6: Warm up
B7: 1 | C7: Phase 1: Foundation Steps 1-3 | D7: 2 | E7: 5 | F7: Review | G7: Waltz | H7: Smooth | I7: Closed | J7: 1-3 | K7: Review Waltz steps
B8: 1 | C8: Phase 1: Foundation Steps 1-3 | D8: 3 | E8: 12 | F8: Closed Steps | G8: Waltz | H8: Smooth | I8: Closed | J8: 1,2,3 | K8: Closed bronze steps 1, 2, 3
B9: 1 | C9: Phase 1: Foundation Steps 1-3 | D9: 4 | E9: 15 | F9: Open Work | G9: Waltz | H9: Smooth | I9: Open | J9: N/A | K9: Open Waltz
B10: 1 | C10: Phase 1: Foundation Steps 1-3 | D10: 5 | E10: 5 | F10: Preview | G10: All Smooth | H10: Smooth | I10: N/A | J10: N/A | K10: Preview Smooth dances
B11: 2 | C11: Phase 1: Foundation Steps 1-3 | D11: 1 | E11: 3 | F11: Warm Up | G11: All | H11: General | I11: N/A | J11: N/A | K11: Warm up
B12: 2 | C12: Phase 1: Foundation Steps 1-3 | D12: 2 | E12: 5 | F12: Review | G12: Cha Cha | H12: Rhythm | I12: Closed | J12: 1-3 | K12: Review closed Cha Cha steps
B13: 2 | C13: Phase 1: Foundation Steps 1-3 | D13: 3 | E13: 15 | F13: Closed Steps | G13: Cha Cha | H13: Rhythm | I13: Closed | J13: 1,2,3 | K13: Closed Cha Cha steps 1, 2, 3
B14: 2 | C14: Phase 1: Foundation Steps 1-3 | D14: 4 | E14: 15 | F14: Open Work | G14: Cha Cha | H14: Rhythm | I14: Open | J14: N/A | K14: Open Cha Cha connection
B15: 2 | C15: Phase 1: Foundation Steps 1-3 | D15: 5 | E15: 5 | F15: Styling | G15: Cha Cha | H15: Rhythm | I15: N/A | J15: N/A | K15: Arm styling
B16: 3 | C16: Phase 1: Foundation Steps 1-3 | D16: 1 | E16: 3 | F16: Warm Up | G16: All | H16: General | I16: N/A | J16: N/A | K16: Warm up
B17: 3 | C17: Phase 1: Foundation Steps 1-3 | D17: 2 | E17: 5 | F17: Preview | G17: Waltz | H17: Smooth | I17: Closed | J17: N/A | K17: Preview Waltz closed steps
... B37: 8 | C37: Phase 1: Foundation Steps 1-3 | D37: 3 | E37: 15 | F37: Closed Steps | G37: Mambo | H37: Rhythm | I37: Closed | J37: 1,2,3 | K37: Closed Mambo steps 1, 2, 3
B38: 8 | C38: Phase 1: Foundation Steps 1-3 | D38: 4 | F38: Rounds | G38: All | H38: General | I38: Closed | J38: N/A | K38: Closed rounds
B39: 9 | C39: Phase 1: Foundation Steps 1-3 | D39: 1 | E39: 3 | F39: Warm Up | G39: All | H39: General | I39: N/A | J39: N/A | K39: Warm up
B40: 9 | C40: Phase 1: Foundation Steps 1-3 | D40: 2 | E40: 20 | F40: Review | G40: All Rhythm | H40: Rhythm | I40: Closed | J40: N/A | K40: Review closed Rhythm
B41: 9 | C41: Phase 1: Foundation Steps 1-3 | D41: 3 | E41: 20 | F41: Review | G41: All Smooth | H41: Smooth | I41: Closed | J41: N/A | K41: Review closed Smooth
B42: 10 | C42: Phase 2: Early Rounds Test | D42: 1 | E42: 3 | F42: Warm Up | G42: All | H42: General | I42: N/A | J42: N/A | K42: Warm up
B43: 10 | C43: Phase 2: Early Rounds Test | D43: 2 | E43: 20 | F43: Rounds | G43: All Smooth | H43: Smooth | I43: Open | J43: N/A | K43: Open Smooth rounds
B44: 10 | C44: Phase 2: Early Rounds Test | D44: 3 | E44: 20 | F44: Rounds | G44: All Smooth | H44: Smooth | I44: Closed | J44: N/A | K44: Closed Smooth rounds
B45: 11 | C45: Phase 2: Early Rounds Test | D45: 1 | E45: 3 | F45: Warm Up | G45: All | H45: General | I45: N/A | J45: N/A | K45: Warm up
B46: 11 | C46: Phase 2: Early Rounds Test | D46: 2 | E46: 15 | F46: Open Work | G46: Bolero | H46: Rhythm | I46: Open | J46: N/A | K46: Open Bolero appearance
B47: 11 | C47: Phase 2: Early Rounds Test | D47: 3 | E47: 20 | F47: Open Work | G47: Mambo | H47: Rhythm | I47: Open | J47: N/A | K47: Open Mambo steps and footwork
B48: 12 | C48: Phase 2: Early Rounds Test | D48: 1 | E48: 3 | F48: Warm Up | G48: All | H48: General | I48: N/A | J48: N/A | K48: Warm up
B49: 12 | C49: Phase 2: Early Rounds Test | D49: 2 | E49: 10 | F49: Rounds | G49: All Rhythm | H49: Rhythm | I49: Closed | J49: N/A | K49: Closed Rhythm rounds
B50: 12 | C50: Phase 2: Early Rounds Test | D50: 3 | E50: 20 | F50: Rounds | G50: All Rhythm | H50: Rhythm | I50: Open | J50: N/A | K50: Open Rhythm rounds
... B89: 21 | C89: Phase 4: Slow Motion Technique | D89: 2 | E89: 5 | F89: Technique | G89: All | H89: General | I89: N/A | J89: N/A | K89: Technique: forward and back steps
B90: 21 | C90: Phase 4: Slow Motion Technique | D90: 3 | F90: Slow Motion | G90: All Smooth | H90: Smooth | I90: Closed | J90: N/A | K90: Smooth 2 rounds in slow motion, closed bronze
B91: 21 | C91: Phase 4: Slow Motion Technique | D91: 4 | F91: Rest Round | G91: All Smooth | H91: Smooth | I91: Closed | J91: N/A | K91: 2 rest rounds
B92: 22 | C92: Phase 4: Slow Motion Technique | D92: 1 | E92: 3 | F92: Warm Up | G92: All | H92: General | I92: N/A | J92: N/A | K92: Warm up
B93: 22 | C93: Phase 4: Slow Motion Technique | D93: 2 | E93: 5 | F93: Technique | G93: All | H93: General | I93: N/A | J93: N/A | K93: Forward and backward technique
B94: 22 | C94: Phase 4: Slow Motion Technique | D94: 3 | F94: Slow Motion | G94: Waltz, Viennese Waltz, Foxtrot | H94: Smooth | I94: Open | J94: N/A | K94: Open slow motion round, then stop and go round
B95: 22 | C95: Phase 4: Slow Motion Technique | D95: 4 | F95: Rest Round | G95: All Smooth | H95: Smooth | I95: Open | J95: N/A | K95: Rest round
B96: 23 | C96: Phase 4: Slow Motion Technique | D96: 1 | E96: 3 | F96: Warm Up | G96: All | H96: General | I96: N/A | J96: N/A | K96: Warm up
B97: 23 | C97: Phase 4: Slow Motion Technique | D97: 2 | F97: Slow Motion | G97: All Rhythm | H97: Rhythm | I97: Closed | J97: N/A | K97: Same format as Lesson 21 applied to Rhythm, closed bronze
B98: 23 | C98: Phase 4: Slow Motion Technique | D98: 3 | F98: Rest Round | G98: All Rhythm | H98: Rhythm | I98: Closed | J98: N/A | K98: Rest round
B99: 24 | C99: Phase 4: Slow Motion Technique | D99: 1 | E99: 3 | F99: Warm Up | G99: All | H99: General | I99: N/A | J99: N/A | K99: Warm up
...

Sheet Lesson Summary
B2: Lesson Summary
B3: Minutes are pulled from the Lesson Blocks sheet with formulas. Blank blocks in the handwriting have no stated duration.
B5: Lesson | C5: Phase | D5: Blocks | E5: Stated Minutes | F5: Focus of the Lesson | G5: Primary Dances
B6: 1 | C6: Phase 1: Foundation Steps 1-3 | D6: =COUNTIF('Lesson Blocks'!$B$6:$B$114,$B6) -> 5 | E6: =SUMIF('Lesson Blocks'!$B$6:$B$114,$B6,'Lesson Blocks'!$E$6:$E$114) -> 40 | F6: Waltz closed steps 1-3 and open Waltz, plus a Smooth preview | G6: Waltz
B7: 2 | C7: Phase 1: Foundation Steps 1-3 | D7: =COUNTIF('Lesson Blocks'!$B$6:$B$114,$B7) -> 5 | E7: =SUMIF('Lesson Blocks'!$B$6:$B$114,$B7,'Lesson Blocks'!$E$6:$E$114) -> 43 | F7: Cha Cha closed steps 1-3, open connection, arm styling | G7: Cha Cha
B8: 3 | C8: Phase 1: Foundation Steps 1-3 | D8: =COUNTIF('Lesson Blocks'!$B$6:$B$114,$B8) -> 4 | E8: =SUMIF('Lesson Blocks'!$B$6:$B$114,$B8,'Lesson Blocks'!$E$6:$E$114) -> 38 | F8: Tango closed steps 1-3 and open Foxtrot | G8: Tango, Foxtrot
B9: 4 | C9: Phase 1: Foundation Steps 1-3 | D9: =COUNTIF('Lesson Blocks'!$B$6:$B$114,$B9) -> 4 | E9: =SUMIF('Lesson Blocks'!$B$6:$B$114,$B9,'Lesson Blocks'!$E$6:$E$114) -> 43 | F9: Rumba closed steps 1-3 and open Rumba connection | G9: Rumba
B10: 5 | C10: Phase 1: Foundation Steps 1-3 | D10: =COUNTIF('Lesson Blocks'!$B$6:$B$114,$B10) -> 4 | E10: =SUMIF('Lesson Blocks'!$B$6:$B$114,$B10,'Lesson Blocks'!$E$6:$E$114) -> 40 | F10: Foxtrot closed steps 1-3 and open Foxtrot footwork | G10: Waltz, Tango, Foxtrot
B11: 6 | C11: Phase 1: Foundation Steps 1-3 | D11: =COUNTIF('Lesson Blocks'!$B$6:$B$114,$B11) -> 3 | E11: =SUMIF('Lesson Blocks'!$B$6:$B$114,$B11,'Lesson Blocks'!$E$6:$E$114) -> 38 | F11: Swing steps 1-3 and open Swing connection | G11: Swing
B12: 7 | C12: Phase 1: Foundation Steps 1-3 | D12: =COUNTIF('Lesson Blocks'!$B$6:$B$114,$B12) -> 4 | E12: =SUMIF('Lesson Blocks'!$B$6:$B$114,$B12,'Lesson Blocks'!$E$6:$E$114) -> 48 | F12: Viennese Waltz closed and open, first Smooth rounds | G12: Viennese Waltz, Smooth
B13: 8 | C13: Phase 1: Foundation Steps 1-3 | D13: =COUNTIF('Lesson Blocks'!$B$6:$B$114,$B13) -> 4 | E13: =SUMIF('Lesson Blocks'!$B$6:$B$114,$B13,'Lesson Blocks'!$E$6:$E$114) -> 33 | F13: Bolero and Mambo closed steps 1-3, closed rounds | G13: Bolero, Mambo
B14: 9 | C14: Phase 1: Foundation Steps 1-3 | D14: =COUNTIF('Lesson Blocks'!$B$6:$B$114,$B14) -> 3 | E14: =SUMIF('Lesson Blocks'!$B$6:$B$114,$B14,'Lesson Blocks'!$E$6:$E$114) -> 43 | F14: Consolidation review of all closed Rhythm and closed Smooth | G14: All
B15: 10 | C15: Phase 2: Early Rounds Test | D15: =COUNTIF('Lesson Blocks'!$B$6:$B$114,$B15) -> 3 | E15: =SUMIF('Lesson Blocks'!$B$6:$B$114,$B15,'Lesson Blocks'!$E$6:$E$114) -> 43 | F15: Smooth rounds, open and closed | G15: All Smooth
B16: 11 | C16: Phase 2: Early Rounds Test | D16: =COUNTIF('Lesson Blocks'!$B$6:$B$114,$B16) -> 3 | E16: =SUMIF('Lesson Blocks'!$B$6:$B$114,$B16,'Lesson Blocks'!$E$6:$E$114) -> 38 | F16: Open Bolero appearance and open Mambo footwork | G16: Bolero, Mambo
B17: 12 | C17: Phase 2: Early Rounds Test | D17: =COUNTIF('Lesson Blocks'!$B$6:$B$114,$B17) -> 3 | E17: =SUMIF('Lesson Blocks'!$B$6:$B$114,$B17,'Lesson Blocks'!$E$6:$E$114) -> 33 | F17: Rhythm rounds, closed and open | G17: All Rhythm
... B35: 30 | C35: Phase 6: Video and Progress Check | D35: =COUNTIF('Lesson Blocks'!$B$6:$B$114,$B35) -> 1 | E35: =SUMIF('Lesson Blocks'!$B$6:$B$114,$B35,'Lesson Blocks'!$E$6:$E$114) -> 0 | F35: Progress check comparing the videos | G35: All
C36: Total | D36: =SUM(D6:D35) -> 109 | E36: =SUM(E6:E35) -> 854

Sheet Phase Map
B2: Phase Map and Method Notes
B4: Phase | C4: Lessons | D4: What Happens | E4: Bruce Lee Principle Applied
B5: Phase 1: Foundation Steps 1-3 | C5: 1-9 | D5: Steps 1, 2, 3 learned closed then opened in all nine dances, with a review block opening almost every lesson. | E5: One kick 10,000 times: same three steps revisited across all nine dances
B6: Phase 2: Early Rounds Test | C6: 10-12 | D6: Full Smooth and Rhythm rounds, closed and open, plus open Bolero and Mambo work. | E6: Functionality over form: test under full-round pressure before it feels ready
B7: Phase 3: Steps 4-5 and Blending | C7: 13-20 | D7: Steps 4 and 5 added dance by dance, with explicit blend all steps blocks and one open expression block. | E7: Add and integrate: new steps blended into existing material, never bolted on
B8: Phase 4: Slow Motion Technique | C8: 21-24 | D8: Forward and backward technique, slow motion rounds, stop and go rounds, rest rounds, Smooth then Rhythm. | E8: Remove momentum so habits become visible
B9: Phase 5: Single Focus and Coaching | C9: 25-27 | D9: Dancing with one thought such as posture, connection and technique work, and studio coaching on heel and leg action. | E9: One instruction at a time, plus outside eyes
B10: Phase 6: Video and Progress Check | C10: 28-30 | D10: Video capture of closed and open work, then a progress check comparing the footage. | E10: Keep records and review them, as Lee did in his training journals
B12: Reading Notes
B13: Style groups | C13: Smooth = Waltz, Tango, Foxtrot, Viennese Waltz. Rhythm = Cha Cha, Rumba, Swing, Bolero, Mambo.
B14: Closed vs Open | C14: Closed refers to closed or bronze-level material danced in closed position. Open refers to open-level figures and connection work.
B15: Blank minutes | C15: Some blocks in the handwritten plan have no stated duration, so the Minutes column is left blank for those rows rather than estimated.
B16: Lesson 30 note | C16: The final line of the handwritten plan after progress check and comparing the videos is not fully legible and is recorded here as the progress check only.
B17: Source | C17: Transcribed from the two handwritten lesson plan sheets dated 2026-09-08.
